<?xml version="1.0" ?>
<!-- =================================================================================== -->
<!-- |    This document was autogenerated by xacro from omnibot2.xacro                 | -->
<!-- |    EDITING THIS FILE BY HAND IS NOT RECOMMENDED                                 | -->
<!-- =================================================================================== -->
<robot name="robot">
  <!-- This mobile robot moves as a diff-drive robot -->
  <!-- BASE -->
  <link name="base_footprint"/>
  <joint name="base_joint" type="fixed">
    <parent link="base_footprint"/>
    <child link="base_link"/>
    <origin rpy="0 0 0" xyz="0 0 0.08"/>
  </joint>
  <link name="base_link">
    <visual>
      <origin rpy="0 0 0" xyz="0 0 0.025"/>
      <geometry>
        <box size="0.3 0.2 0.005"/>
        <!-- Main block -->
      </geometry>
      <material name="grey">
        <color rgba="0.8 0.8 0.8 1.0"/>
      </material>
    </visual>
    <!-- Frontal part to define the robot orientation -->
    <visual>
      <origin rpy="0 0 0" xyz="0.1 0 0.045"/>
      <geometry>
        <box size="0.07 0.076 0.03"/>
      </geometry>
    </visual>
    <collision>
      <origin rpy="0 0 0" xyz="0 0 0.025"/>
      <geometry>
        <box size="0.3 0.2 0.01"/>
      </geometry>
    </collision>
    <inertial>
      <origin rpy="0 0 0" xyz="0 0 0.0"/>
      <mass value="20.0"/>
      <inertia ixx="2.133" ixy="0" ixz="0" iyy="4.266" iyz="0" izz="5.546"/>
    </inertial>
  </link>
  <joint name="leftfront_joint" type="continuous">
    <origin rpy="-1.570796325 0 0" xyz="0.085 0.14 0.01"/>
    <parent link="base_link"/>
    <child link="leftfront_link"/>
    <axis xyz="0 0 1"/>
  </joint>
  <link name="leftfront_link">
    <visual>
      <origin rpy="-1.570796325 0 0" xyz="0 0 0"/>
      <geometry>
        <mesh filename="package://ign_robots_examples/meshes/left_mecanum_wheel.dae" scale="1.0 0.8 1.0"/>
      </geometry>
    </visual>
    <collision>
      <origin rpy="0 0 0" xyz="0 0 0"/>
      <geometry>
        <cylinder length="0.05" radius="0.05"/>
      </geometry>
    </collision>
    <inertial>
      <origin xyz="0 0 0"/>
      <mass value="0.1"/>
      <inertia ixx="6.1e-5" ixy="0" ixz="0" iyy="6.1e-5" iyz="0" izz="6.1e-5"/>
    </inertial>
  </link>
  <joint name="rightfront_joint" type="continuous">
    <origin rpy="-1.570796325 0 0" xyz="0.085 -0.14 0.01"/>
    <parent link="base_link"/>
    <child link="rightfront_link"/>
    <axis xyz="0 0 1"/>
  </joint>
  <link name="rightfront_link">
    <visual>
      <origin rpy="-1.570796325 0 0" xyz="0 0 0"/>
      <geometry>
        <mesh filename="package://ign_robots_examples/meshes/right_mecanum_wheel.dae" scale="1.0 0.8 1.0"/>
      </geometry>
    </visual>
    <collision>
      <origin rpy="0 0 0" xyz="0 0 0"/>
      <geometry>
        <cylinder length="0.05" radius="0.05"/>
      </geometry>
    </collision>
    <inertial>
      <origin xyz="0 0 0"/>
      <mass value="0.1"/>
      <inertia ixx="6.1e-5" ixy="0" ixz="0" iyy="6.1e-5" iyz="0" izz="6.1e-5"/>
    </inertial>
  </link>
  <joint name="rightback_joint" type="continuous">
    <origin rpy="-1.570796325 0 0" xyz="-0.085 -0.14 0.01"/>
    <parent link="base_link"/>
    <child link="rightback_link"/>
    <axis xyz="0 0 1"/>
  </joint>
  <link name="rightback_link">
    <visual>
      <origin rpy="-1.570796325 0 0" xyz="0 0 0"/>
      <geometry>
        <mesh filename="package://ign_robots_examples/meshes/left_mecanum_wheel.dae" scale="1.0 0.8 1.0"/>
      </geometry>
    </visual>
    <collision>
      <origin rpy="0 0 0" xyz="0 0 0"/>
      <geometry>
        <cylinder length="0.05" radius="0.05"/>
      </geometry>
    </collision>
    <inertial>
      <origin xyz="0 0 0"/>
      <mass value="0.1"/>
      <inertia ixx="6.1e-5" ixy="0" ixz="0" iyy="6.1e-5" iyz="0" izz="6.1e-5"/>
    </inertial>
  </link>
  <joint name="leftback_joint" type="continuous">
    <origin rpy="-1.570796325 0 0" xyz="-0.085 0.14 0.01"/>
    <parent link="base_link"/>
    <child link="leftback_link"/>
    <axis xyz="0 0 1"/>
  </joint>
  <link name="leftback_link">
    <visual>
      <origin rpy="-1.570796325 0 0" xyz="0 0 0"/>
      <geometry>
        <mesh filename="package://ign_robots_examples/meshes/right_mecanum_wheel.dae" scale="1.0 0.8 1.0"/>
      </geometry>
    </visual>
    <collision>
      <origin rpy="0 0 0" xyz="0 0 0"/>
      <geometry>
        <cylinder length="0.05" radius="0.05"/>
      </geometry>
    </collision>
    <inertial>
      <origin xyz="0 0 0"/>
      <mass value="0.1"/>
      <inertia ixx="6.1e-5" ixy="0" ixz="0" iyy="6.1e-5" iyz="0" izz="6.1e-5"/>
    </inertial>
  </link>
  <!-- ************************ SENSORS DEFINITION ***************************** -->
  <!-- LIDAR -->
  <joint name="lidar_joint" type="fixed">
    <parent link="base_link"/>
    <child link="lidar_link"/>
    <origin rpy="0 0 0" xyz="0.1 0 0.15"/>
  </joint>
  <link name="lidar_link">
    <visual>
      <origin rpy="0 0 0" xyz="0 0 0"/>
      <geometry>
        <cylinder length="0.07" radius="0.04"/>
      </geometry>
      <material name="black">
        <color rgba="0 0 0 1"/>
      </material>
    </visual>
  </link>
  <gazebo reference="lidar_link">
    <sensor name="gpu_lidar" type="gpu_lidar">
      &quot;
      
      <ignition_frame_id>lidar_link</ignition_frame_id>
      <update_rate>10</update_rate>
      <ray>
        <scan>
          <horizontal>
            <samples>360</samples>
            <resolution>1</resolution>
            <min_angle>-2.1</min_angle>
            <max_angle>2.1</max_angle>
          </horizontal>
        </scan>
        <range>
          <min>0.1</min>
          <max>40.0</max>
          <resolution>0.017453</resolution>
        </range>
        <noise>
          <type>gaussian</type>
          <mean>0.0</mean>
          <stddev>0.01</stddev>
        </noise>
      </ray>
      <alwaysOn>1</alwaysOn>
      <visualize>false</visualize>
      <topic>lidar</topic>
    </sensor>
  </gazebo>
  <!-- RGBD CAMERA -->
  <joint name="rgbd_joint" type="fixed">
    <origin rpy="0 0 0" xyz="0.18 0 0.06"/>
    <parent link="base_link"/>
    <child link="rgbd_frame"/>
  </joint>
  <link name="rgbd_frame">
    <visual>
      <origin rpy="0 0 0" xyz="0 0 0"/>
      <geometry>
        <box size="0.02 0.07 0.03"/>
      </geometry>
      <material name="white">
        <color rgba="0.9 0.9 0.9 1.0"/>
      </material>
    </visual>
  </link>
  <gazebo reference="rgbd_frame">
    <sensor name="rgbd_camera" type="rgbd_camera">
      <ignition_frame_id>rgbd_frame</ignition_frame_id>
      <camera name="rgbd_frame">
        <horizontal_fov>1.0472</horizontal_fov>
        <lens>
          <intrinsics>
            <!-- fx = fy = width / ( 2 * tan (hfov / 2 ) ) -->
            <fx>277.1</fx>
            <fy>277.1</fy>
            <!-- cx = ( width + 1 ) / 2 -->
            <cx>160.5</cx>
            <!-- cy = ( height + 1 ) / 2 -->
            <cy>120.5</cy>
            <s>0</s>
          </intrinsics>
        </lens>
        <distortion>
          <k1>0.0</k1>
          <k2>0.0</k2>
          <k3>0.0</k3>
          <p1>0.0</p1>
          <p2>0.0</p2>
          <center>0.5 0.5</center>
        </distortion>
        <image>
          <width>320</width>
          <height>240</height>
          <format>R8G8B8</format>
        </image>
        <clip>
          <near>0.01</near>
          <far>300</far>
        </clip>
        <depth_camera>
          <clip>
            <near>0.1</near>
            <far>10</far>
          </clip>
        </depth_camera>
        <noise>
          <type>gaussian</type>
          <mean>0</mean>
          <stddev>0.004</stddev>
        </noise>
      </camera>
      <always_on>1</always_on>
      <update_rate>10</update_rate>
      <visualize>0</visualize>
      <topic>depth_camera</topic>
    </sensor>
  </gazebo>
  <!-- IMU -->
  <gazebo reference="base_link">
    <sensor name="imu_sensor" type="imu">
      <ignition_frame_id>base_link</ignition_frame_id>
      <always_on>1</always_on>
      <update_rate>50</update_rate>
      <visualize>false</visualize>
      <topic>imu</topic>
      <imu>
        <enable_orientation>0</enable_orientation>
        <angular_velocity>
          <x>
            <noise type="gaussian">
              <mean>0</mean>
              <stddev>0.009</stddev>
              <bias_mean>0.00075</bias_mean>
              <bias_stddev>0.005</bias_stddev>
              <dynamic_bias_stddev>0.00002</dynamic_bias_stddev>
              <dynamic_bias_correlation_time>400.0</dynamic_bias_correlation_time>
              <precision>0.00025</precision>
            </noise>
          </x>
          <y>
            <noise type="gaussian">
              <mean>0</mean>
              <stddev>0.009</stddev>
              <bias_mean>0.00075</bias_mean>
              <bias_stddev>0.005</bias_stddev>
              <dynamic_bias_stddev>0.00002</dynamic_bias_stddev>
              <dynamic_bias_correlation_time>400.0</dynamic_bias_correlation_time>
              <precision>0.00025</precision>
            </noise>
          </y>
          <z>
            <noise type="gaussian">
              <mean>0</mean>
              <stddev>0.009</stddev>
              <bias_mean>0.00075</bias_mean>
              <bias_stddev>0.005</bias_stddev>
              <dynamic_bias_stddev>0.00002</dynamic_bias_stddev>
              <dynamic_bias_correlation_time>400.0</dynamic_bias_correlation_time>
              <precision>0.00025</precision>
            </noise>
          </z>
        </angular_velocity>
        <linear_acceleration>
          <x>
            <noise type="gaussian">
              <mean>0</mean>
              <stddev>0.021</stddev>
              <bias_mean>0.05</bias_mean>
              <bias_stddev>0.0075</bias_stddev>
              <dynamic_bias_stddev>0.000375</dynamic_bias_stddev>
              <dynamic_bias_correlation_time>175.0</dynamic_bias_correlation_time>
              <precision>0.005</precision>
            </noise>
          </x>
          <y>
            <noise type="gaussian">
              <mean>0</mean>
              <stddev>0.021</stddev>
              <bias_mean>0.05</bias_mean>
              <bias_stddev>0.0075</bias_stddev>
              <dynamic_bias_stddev>0.000375</dynamic_bias_stddev>
              <dynamic_bias_correlation_time>175.0</dynamic_bias_correlation_time>
              <precision>0.005</precision>
            </noise>
          </y>
          <z>
            <noise type="gaussian">
              <mean>0</mean>
              <stddev>0.021</stddev>
              <bias_mean>0.05</bias_mean>
              <bias_stddev>0.0075</bias_stddev>
              <dynamic_bias_stddev>0.000375</dynamic_bias_stddev>
              <dynamic_bias_correlation_time>175.0</dynamic_bias_correlation_time>
              <precision>0.005</precision>
            </noise>
          </z>
        </linear_acceleration>
      </imu>
    </sensor>
  </gazebo>
  <gazebo>
    <plugin filename="ignition-gazebo-mecanum-drive-system" name="ignition::gazebo::systems::MecanumDrive">
      <front_left_joint>leftfront_joint</front_left_joint>
      <front_right_joint>rightfront_joint</front_right_joint>
      <back_left_joint>leftback_joint</back_left_joint>
      <back_right_joint>rightback_joint</back_right_joint>
      <wheel_separation>0.085</wheel_separation>
      <!--Lx-->
      <wheelbase>0.14</wheelbase>
      <!--Ly-->
      <wheel_radius>0.05</wheel_radius>
      <min_acceleration>-5</min_acceleration>
      <max_acceleration>5</max_acceleration>
      <!--odom_topic>encoder</odom_topic> <THIS TAG IS REQUIRED TO USE THE WORLD PLUGIN-->
    </plugin>
    <!-- World odometry plugin (by default, odometry topic is used) -->
    <plugin filename="ignition-gazebo-odometry-publisher-system" name="ignition::gazebo::systems::OdometryPublisher">
      <dimensions>3</dimensions>
      <robot_base_frame>base_footprint</robot_base_frame>
    </plugin>
    <plugin filename="ignition-gazebo-joint-state-publisher-system" name="ignition::gazebo::systems::JointStatePublisher">
    </plugin>
    <plugin filename="ignition-gazebo-joint-state-publisher-system" name="ignition::gazebo::systems::JointStatePublisher">
    </plugin>
  </gazebo>
</robot>
